<?xml version="1.0"?>
<!-- multi_wheel_control.urdf -->
<robot name="multi_wheel_control_robot">

  <!-- ホイールのリンク -->
  <link name="left_wheel">
    <visual>
      <!-- ホイールの外観 -->
      <geometry>
        <cylinder length="0.03" radius="0.07"/>
      </geometry>
      <material name="grey">
        <color rgba="0.5 0.5 0.5 1"/>
      </material>
    </visual>
  </link>

  <link name="right_wheel">
    <visual>
      <geometry>
        <cylinder length="0.03" radius="0.07"/>
      </geometry>
      <material name="grey">
        <color rgba="0.5 0.5 0.5 1"/>
      </material>
    </visual>
  </link>

  <!-- ロボットのベース -->
  <link name="base_link">
    <!-- ロボットの外観 -->
    <visual>
      <geometry>
        <box size="0.4 0.4 0.4"/>
      </geometry>
      <material name="red">
        <color rgba="1 0 0 1"/>
      </material>
    </visual>
  </link>

  <!-- ホイールのジョイント -->
  <joint name="left_wheel_joint" type="continuous">
    <axis xyz="0 0 1"/>
    <parent link="base_link"/>
    <child link="left_wheel"/>
    <origin xyz="-0.13 0.2 -0.15" rpy = "-1.5708 0 0"/>
  </joint>

  <joint name="right_wheel_joint" type="continuous">
    <axis xyz = "0 0 1"/>
    <parent link="base_link"/>
    <child link="right_wheel"/>
    <origin xyz="-0.13 -0.2 -0.15" rpy = "-1.5708 0 0"/>
  </joint>

  <!-- Gazeboプラグインの追加 -->
  <ros2_control name="GazeboSystem" type="system">
    <hardware>
      <plugin>gazebo_ros2_control/GazeboSystem</plugin>
    </hardware>
  </ros2_control>

  <gazebo>
    <plugin filename="libgazebo_ros2_control.so" name="gazebo_ros2_control">
      <robot_param>robot_description</robot_param>
      <robot_param_node>robot_state_publisher</robot_param_node>
    </plugin>
  </gazebo>
</robot>
